Workbook

Sheet Cover
B2: NEW-AGE DEFENCE PRIME | 10-YEAR STRATEGIC PLAN
B3: Platform-Based Engineering - Multi-Domain (Air | Land | Sea | Cyber)
B5: Company thesis | C5: A new-age defense prime built on owned IP across six product verticals. All six are already designed; V2 EW/SIGINT is GSQR-compliant with a committed Rs.200 Cr iDEX MoQ for 10 airborne ESM units now in prototype trials. Capital deployed against prototyping, qualification, and production line stand-up - not greenfield invention. Five reusable platform modules (RF, DSP, SysEng, Embedded/SW, AI/ML) compound R&D leverage across verticals.
B6: Operating model | C6: Industrialise mature designs in parallel. Cross-functional product squads, short qualification cycles (12-24 months MVP-to-field) enabled by pre-existing design IP and 10% bank-confirmed BG cash margin. Concurrent development + production across verticals.
B7: Product verticals | C7: 1) AESA Radar (first ship Y2) | 2) EW & SIGINT (Rs.200 Cr iDEX MoQ in trials, ship Y1) | 3) Counter-UAS (Y3) | 4) MALE ISR UAS (end-Y3) | 5) Autonomous AUV/USV (Y3) | 6) Military AI modules (Y2)
B8: Core USP | C8: Owned IP across six fielded product lines inside Y3. Five reusable platform modules. Bank-confirmed 10% BG margin from Day 1 unlocks capital efficiency. iDEX-validated ESM anchor de-risks the funding ask. Cross-domain coverage Air/Land/Sea/Cyber from a single engineering org.
B9: Planning horizon | C9: 10 years | Currency: INR Crores | All cells with yellow background are inputs.
B10: Cell colour key | C10: Yellow = input | Light blue = calculated | Darker blue = total/subtotal | Navy bar = section header
B11: Read order | C11: Cover to KPIs to Strategy to MarketPositioning to Roadmap to Platform to ReuseMatrix to Assumptions to V1..V6 (per-vertical) to Revenue to Headcount to R&D_NRE to Capex to Opex to P&L to CashFlow to Funding to BreakEven
B13: Product verticals at a glance
B14: Code | C14: Vertical | D14: Domain | E14: Launch | F14: Sheet
B15: V1 | C15: AESA Radar | D15: Air/Land/Sea (RF) | E15: Y2 | F15: V1_AESA
B16: V2 | C16: Electronic Warfare & SIGINT | D16: Air/Land/Sea (RF + DSP) | E16: Y1 | F16: V2_EW_SIGINT
B17: V3 | C17: Counter-UAS (Anti-Drone) | D17: Land/Air (RF + AI fusion) | E17: Y2 | F17: V3_CUAS
B18: V4 | C18: MALE-class ISR UAS | D18: Air (SysEng + SW + AI) | E18: Y4 | F18: V4_UAS_MALE
B19: V5 | C19: Autonomous Systems (AUV/USV) | D19: Sea (SysEng + SW + AI) | E19: Y3 | F19: V5_Autonomous
B20: V6 | C20: Military AI Systems | D20: Cross-domain (AI/SW) | E20: Y1 | F20: V6_MilAI

Sheet KPIs
B2: CXO EXECUTIVE SUMMARY
B3: Year 10 Revenue | D3: Year 10 EBITDA (margin) | F3: 10-Yr Cumulative FCF | H3: IRR (10-Yr FCF) | J3: NPV @ Disc. Rate (WACC)
B4: ='P&L'!L5 -> 5055.32 | D4: ="₹ "&TEXT('P&L'!L16,"#,##0.0")&" Cr ("&TEXT(IFERROR('P&L'!L16/'P&L'!L5,0),"0.0%")&")" -> ₹ 2,347.1 Cr (46.4%) | F4: =SUM(CashFlow!C27:L27) -> 4803.2655 | H4: =IFERROR(IRR(CashFlow!C27:L27),0) -> 0.31896859 | J4: =NPV(Assumptions!$C$7,CashFlow!C27:L27) -> 747.15263
B6: Executive KPI Dashboard - Diversified Defense & Aerospace
B8: Metric | C8: Y1 | D8: Y2 | E8: Y3 | F8: Y4 | G8: Y5 | H8: Y6 | I8: Y7 | J8: Y8 | K8: Y9 | L8: Y10
B9: Total revenue | C9: ='P&L'!C5 -> 52.5 | D9: ='P&L'!D5 -> 203.4075 | E9: ='P&L'!E5 -> 491.02541 | F9: ='P&L'!F5 -> 855.20352 | G9: ='P&L'!G5 -> 1447.7017 | H9: ='P&L'!H5 -> 2180.2274 | I9: ='P&L'!I5 -> 2883.8462 | J9: ='P&L'!J5 -> 3659.344 | ... L9: ='P&L'!L5 -> 5055.32
B10: Revenue growth Y/Y | C10: =0 -> 0 | D10: =IFERROR(D9/C9-1,0) -> 2.8744286 | E10: =IFERROR(E9/D9-1,0) -> 1.4139985 | F10: =IFERROR(F9/E9-1,0) -> 0.74166858 | G10: =IFERROR(G9/F9-1,0) -> 0.69281543 | H10: =IFERROR(H9/G9-1,0) -> 0.50599213 | I10: =IFERROR(I9/H9-1,0) -> 0.32272726 | J10: =IFERROR(J9/I9-1,0) -> 0.26891092 | K10: =IFERROR(K9/J9-1,0) -> 0.19711563 | L10: =IFERROR(L9/K9-1,0) -> 0.15400931
B11: Gross profit | C11: ='P&L'!C9 -> 27.011617 | D11: ='P&L'!D9 -> 117.73007 | E11: ='P&L'!E9 -> 311.47721 | F11: ='P&L'!F9 -> 533.2586 | G11: ='P&L'!G9 -> 918.76581 | H11: ='P&L'!H9 -> 1408.7692 | I11: ='P&L'!I9 -> 1885.4316 | J11: ='P&L'!J9 -> 2410.6944 | ... L11: ='P&L'!L9 -> 3377.3479
B12: Gross margin % | C12: =IFERROR(C11/C9,0) -> 0.51450699 | D12: =IFERROR(D11/D9,0) -> 0.57878921 | E12: =IFERROR(E11/E9,0) -> 0.63434031 | F12: =IFERROR(F11/F9,0) -> 0.62354584 | G12: =IFERROR(G11/G9,0) -> 0.63463751 | H12: =IFERROR(H11/H9,0) -> 0.646157 | I12: =IFERROR(I11/I9,0) -> 0.65379063 | J12: =IFERROR(J11/J9,0) -> 0.65877776 | ... L12: =IFERROR(L11/L9,0) -> 0.66807798
B13: R&D / NRE expense | C13: ='P&L'!C12 -> 301.93624 | D13: ='P&L'!D12 -> 347.80873 | E13: ='P&L'!E12 -> 185.21737 | F13: ='P&L'!F12 -> 118.02114 | G13: ='P&L'!G12 -> 80.586228 | H13: ='P&L'!H12 -> 66.911876 | I13: ='P&L'!I12 -> 63.404198 | J13: ='P&L'!J12 -> 65.917668 | ... L13: ='P&L'!L12 -> 68.640795
B14: Counterfactual: NRE avoided by platform reuse (NOT realized cash) | C14: ='R&D_NRE'!D8-'R&D_NRE'!D6 -> 119.89713 | D14: ='R&D_NRE'!E8-'R&D_NRE'!E6 -> 198.60082 | E14: ='R&D_NRE'!F8-'R&D_NRE'!F6 -> 210.94554 | F14: ='R&D_NRE'!G8-'R&D_NRE'!G6 -> 179.76992 | G14: ='R&D_NRE'!H8-'R&D_NRE'!H6 -> 123.16721 | H14: ='R&D_NRE'!I8-'R&D_NRE'!I6 -> 71.689147 | I14: ='R&D_NRE'!J8-'R&D_NRE'!J6 -> 45.874046 | J14: ='R&D_NRE'!K8-'R&D_NRE'!K6 -> 26.464991 | ... L14: ='R&D_NRE'!M8-'R&D_NRE'!M6 -> 8.699625
B15: EBITDA | C15: ='P&L'!C16 -> -324.49623 | D15: ='P&L'!D16 -> -316.78236 | E15: ='P&L'!E16 -> -22.7994 | F15: ='P&L'!F16 -> 190.46392 | G15: ='P&L'!G16 -> 501.69301 | H15: ='P&L'!H16 -> 876.56194 | I15: ='P&L'!I16 -> 1232.8939 | J15: ='P&L'!J16 -> 1622.8415 | ... L15: ='P&L'!L16 -> 2347.0901
B16: EBITDA margin % | C16: =IFERROR(C15/C9,0) -> -6.1808806 | D16: =IFERROR(D15/D9,0) -> -1.557378 | E16: =IFERROR(E15/E9,0) -> -0.046432221 | F16: =IFERROR(F15/F9,0) -> 0.2227118 | G16: =IFERROR(G15/G9,0) -> 0.34654446 | H16: =IFERROR(H15/H9,0) -> 0.40205069 | I16: =IFERROR(I15/I9,0) -> 0.4275172 | J16: =IFERROR(J15/J9,0) -> 0.44347882 | ... L16: =IFERROR(L15/L9,0) -> 0.46428122
B17: Net income | C17: ='P&L'!C24 -> -335.06825 | D17: ='P&L'!D24 -> -355.71344 | E17: ='P&L'!E24 -> -91.417614 | F17: ='P&L'!F24 -> 99.488086 | G17: ='P&L'!G24 -> 400.12777 | H17: ='P&L'!H24 -> 671.23238 | I17: ='P&L'!I24 -> 844.0913 | J17: ='P&L'!J24 -> 1154.5239 | ... L17: ='P&L'!L24 -> 1717.3482
B18: Free cash flow | C18: =CashFlow!C27 -> -359.92178 | D18: =CashFlow!D27 -> -467.73337 | E18: =CashFlow!E27 -> -234.12709 | F18: =CashFlow!F27 -> 2.9927111 | G18: =CashFlow!G27 -> 265.53479 | H18: =CashFlow!H27 -> 571.97389 | I18: =CashFlow!I27 -> 925.83481 | J18: =CashFlow!J27 -> 1071.8306 | ... L18: =CashFlow!L27 -> 1660.8948
B19: Cumulative FCF | C19: =CashFlow!C28 -> -359.92178 | D19: =CashFlow!D28 -> -827.65515 | E19: =CashFlow!E28 -> -1061.7822 | F19: =CashFlow!F28 -> -1058.7895 | G19: =CashFlow!G28 -> -793.25474 | H19: =CashFlow!H28 -> -221.28085 | I19: =CashFlow!I28 -> 704.55396 | J19: =CashFlow!J28 -> 1776.3845 | ... L19: =CashFlow!L28 -> 4803.2655
B20: Cash balance (EoY, deployable) | C20: =CashFlow!C30 -> 110.07822 | D20: =CashFlow!D30 -> 142.34485 | E20: =CashFlow!E30 -> 238.21776 | F20: =CashFlow!F30 -> 241.21047 | G20: =CashFlow!G30 -> 470.74526 | H20: =CashFlow!H30 -> 1006.7191 | I20: =CashFlow!I30 -> 1877.554 | J20: =CashFlow!J30 -> 2884.3845 | ... L20: =CashFlow!L30 -> 5903.2655
B21: Restricted cash (BG collateral) | C21: =Backlog!D63 -> 7.65099 | D21: =Backlog!E63 -> 20.300722 | E21: =Backlog!F63 -> 38.334047 | F21: =Backlog!G63 -> 68.285291 | G21: =Backlog!H63 -> 105.98933 | H21: =Backlog!I63 -> 143.59794 | I21: =Backlog!J63 -> 185.37943 | J21: =Backlog!K63 -> 225.30466 | ... L21: =Backlog!M63 -> 300.23537
B22: Total cash (incl. restricted) | C22: =CashFlow!C30+Backlog!D63 -> 117.72921 | D22: =CashFlow!D30+Backlog!E63 -> 162.64557 | E22: =CashFlow!E30+Backlog!F63 -> 276.5518 | F22: =CashFlow!F30+Backlog!G63 -> 309.49576 | G22: =CashFlow!G30+Backlog!H63 -> 576.73459 | H22: =CashFlow!H30+Backlog!I63 -> 1150.3171 | I22: =CashFlow!I30+Backlog!J63 -> 2062.9334 | J22: =CashFlow!J30+Backlog!K63 -> 3109.6892 | ... L22: =CashFlow!L30+Backlog!M63 -> 6203.5009
B23: Net cash (deployable = Total − Restricted) | C23: =CashFlow!C30 -> 110.07822 | D23: =CashFlow!D30 -> 142.34485 | E23: =CashFlow!E30 -> 238.21776 | F23: =CashFlow!F30 -> 241.21047 | G23: =CashFlow!G30 -> 470.74526 | H23: =CashFlow!H30 -> 1006.7191 | I23: =CashFlow!I30 -> 1877.554 | J23: =CashFlow!J30 -> 2884.3845 | ... L23: =CashFlow!L30 -> 5903.2655
B24: Contract liabilities (customer advances, EoY) | C24: =Backlog!D56 -> 63.75825 | D24: =Backlog!E56 -> 169.17268 | E24: =Backlog!F56 -> 319.45039 | F24: =Backlog!G56 -> 569.04409 | G24: =Backlog!H56 -> 883.24441 | H24: =Backlog!I56 -> 1196.6495 | I24: =Backlog!J56 -> 1544.8286 | J24: =Backlog!K56 -> 1877.5388 | ... L24: =Backlog!M56 -> 2501.9615
B25: Bank guarantees outstanding (PBG + ABG) | C25: =Backlog!D62 -> 76.5099 | D25: =Backlog!E62 -> 203.00722 | E25: =Backlog!F62 -> 383.34047 | F25: =Backlog!G62 -> 682.85291 | G25: =Backlog!H62 -> 1059.8933 | H25: =Backlog!I62 -> 1435.9794 | I25: =Backlog!J62 -> 1853.7943 | J25: =Backlog!K62 -> 2253.0466 | ... L25: =Backlog!M62 -> 3002.3537
B26: Equity raised | C26: =Funding!D9 -> 450 | D26: =Funding!E9 -> 400 | E26: =Funding!F9 -> 250 | F26: =Funding!G9 -> 0 | G26: =Funding!H9 -> 0 | H26: =Funding!I9 -> 0 | I26: =Funding!J9 -> 0 | J26: =Funding!K9 -> 0 | ... L26: =Funding!M9 -> 0
B27: Debt balance (EoY) | C27: =Funding!D16 -> 20 | D27: =Funding!E16 -> 120 | E27: =Funding!F16 -> 200 | F27: =Funding!G16 -> 200 | G27: =Funding!H16 -> 164 | H27: =Funding!I16 -> 128 | I27: =Funding!J16 -> 73 | J27: =Funding!K16 -> 8 | ... L27: =Funding!M16 -> 0
B28: Total headcount (EoY) | C28: =Headcount!D34 -> 91 | D28: =Headcount!E34 -> 156 | E28: =Headcount!F34 -> 216 | F28: =Headcount!G34 -> 287 | G28: =Headcount!H34 -> 349 | H28: =Headcount!I34 -> 414 | I28: =Headcount!J34 -> 475 | J28: =Headcount!K34 -> 506 | ... L28: =Headcount!M34 -> 543
B29: Revenue per employee | C29: =IFERROR(C9/C28,0) -> 0.57692308 | D29: =IFERROR(D9/D28,0) -> 1.3038942 | E29: =IFERROR(E9/E28,0) -> 2.2732658 | F29: =IFERROR(F9/F28,0) -> 2.9798032 | G29: =IFERROR(G9/G28,0) -> 4.1481425 | H29: =IFERROR(H9/H28,0) -> 5.2662498 | I29: =IFERROR(I9/I28,0) -> 6.0712552 | J29: =IFERROR(J9/J28,0) -> 7.2319051 | ... L29: =IFERROR(L9/L28,0) -> 9.3099815
B30: Capex (gross) | C30: =Capex!D21 -> 35.45 | D30: =Capex!E21 -> 67.225 | E30: =Capex!F21 -> 118.15 | F30: =Capex!G21 -> 135.7 | G30: =Capex!H21 -> 94.375 | H30: =Capex!I21 -> 47.1 | I30: =Capex!J21 -> 19.95 | J30: =Capex!K21 -> 29.45 | ... L30: =Capex!M21 -> 22.8
B31: Current ratio (CA / CL = AP + Customer Advances) | C31: =BalanceSheet!C33 -> 2.2407019 | D31: =BalanceSheet!D33 -> 1.5805548 | E31: =BalanceSheet!E33 -> 1.6481141 | F31: =BalanceSheet!F33 -> 1.3316507 | G31: =BalanceSheet!G33 -> 1.4983222 | H31: =BalanceSheet!H33 -> 1.8700988 | I31: =BalanceSheet!I33 -> 2.2370897 | J31: =BalanceSheet!J33 -> 2.5706275 | ... L31: =BalanceSheet!L33 -> 3.3631738
B32: ROIC (NOPAT / Debt+Equity) | C32: =BalanceSheet!C35 -> -1.8579852 | D32: =BalanceSheet!D35 -> -0.94042929 | E32: =BalanceSheet!E35 -> -0.11387241 | F32: =BalanceSheet!F35 -> 0.14031693 | G32: =BalanceSheet!G35 -> 0.31690502 | H32: =BalanceSheet!H35 -> 0.36365647 | I32: =BalanceSheet!I35 -> 0.35666961 | J32: =BalanceSheet!J35 -> 0.33243642 | ... L32: =BalanceSheet!L35 -> 0.25862396
B33: Net Working Capital | C33: =CashFlow!C11 -> 29.032814 | D33: =CashFlow!D11 -> 110.87352 | E33: =CashFlow!E11 -> 264.28559 | F33: =CashFlow!F11 -> 461.43604 | G33: =CashFlow!G11 -> 779.14637 | H33: =CashFlow!H11 -> 1170.2919 | I33: =CashFlow!I11 -> 1545.2629 | J33: =CashFlow!J11 -> 1958.5511 | ... L33: =CashFlow!L11 -> 2699.9078
B35: 10-year cumulative & strategic indicators
B36: Cumulative revenue (10 yr) | C36: =SUM('P&L'!C5:L5) -> 21209.234
B37: Cumulative EBITDA (10 yr) | C37: =SUM('P&L'!C16:L16) -> 8100.0525
B38: Cumulative net income (10 yr) | C38: =SUM('P&L'!C24:L24) -> 5548.2439
B39: Cumulative R&D / NRE expense | C39: =SUM('R&D_NRE'!D12:M12) -> 1365.9421
B40: Cumulative NRE saved by platform | C40: =SUM('R&D_NRE'!D8:M8)-SUM('R&D_NRE'!D6:M6) -> 994.32373
B41: Total equity raised | C41: =SUM(Funding!D9:M9) -> 1100
B42: Total Capex (10 yr) | C42: =SUM(Capex!D21:M21) -> 600.125
B43: NPV of FCF (WACC) | C43: =NPV(Assumptions!$C$7,CashFlow!C27:L27) -> 747.15263
B44: IRR of FCF | C44: =IFERROR(IRR(CashFlow!C27:L27),0) -> 0.31896859
...

Sheet Strategy
B2: Strategic Narrative - New-Age Defense Prime
B4: Vision (10-yr) | C4: Become the reference multi-domain defense technology firm of the new-age prime model - supplier of RF, autonomy and AI products across Air, Land, Sea and Cyber, anchored on a single, deeply reusable engineering platform and shipped on commercial-software cycle times.
B5: Mission | C5: Industrialise six pre-designed defense product lines on commercial-software cycle times. Convert owned IP and the iDEX-anchored ESM contract into a defensible new-age prime: lower NRE per product, faster qualification, compounding gross margin from Year 1.
B6: New-age prime - operating model | C6: Product-focused, software-defined, asset-light. Cross-functional product squads instead of program directorates. Short cycles (12-24 month MVP to field) replace multi-year legacy programs. Concurrent development across verticals while ESM (already partly developed at Day 1) is in production and sales - funding subsequent product lines from operating cash, not just equity. Capex deferred via partner anechoic / EMI / range facilities until volumes justify owned infra.
B7: Operating thesis vs. legacy primes | C7: Legacy primes carry the full NRE burden and the full bureaucracy overhead on every product, on 5-7 year cycles. This firm amortizes RF, DSP, SysEng, SW and AI investment across 6 product lines on 1-3 year cycles, with a productized ESM business funding adjacent products - driving lower NRE per product, faster qualification, and compounding gross margin from Year 1.
B8: Core USP | C8: Multi-domain autonomous + RF systems provider operating like a software company. One certifiable platform, six product lines fielded in 5 years, three domains. We out-cycle single-point vendors on cost-to-deliver and time-to-fielding, and out-scale narrow startups on capability breadth.
B9: Strategic pillars | C9: 1) Platform Engineering - five reusable tech modules (RF · DSP · SysEng · SW · AI). 2) Multi-Domain Coverage - Air (UAS, EW pods, AESA), Land (C-UAS, SIGINT, Mil AI), Sea (AUV, USV). 3) Concurrent Dev + Production - ESM cash funds adjacent product development. 4) IP + Sovereign Capability - cleared workforce + retained data rights + IP-led licensing. 5) Allied + FMS Export - DCS/FMS-eligible product variants from Day 1.
B10: Capability waves (compressed) | C10: Wave 1 (Y1-Y2): Deliver Rs.210 Cr iDEX ESM MoQ; ship V6 Military AI modules; V1 AESA + V3 C-UAS + V4 MALE prototype trials. Wave 2 (Y3): V1 AESA first delivery + V3 C-UAS first orders + V4 MALE end-Y3 first delivery + V5 AUV first delivery. Wave 3 (Y4-Y6): Production ramp across all six verticals + export/FMS variants. Wave 4 (Y7+): Scale, replenishment cycles, allied bids.
B11: Margin trajectory (model output) | C11: Gross margin expands from ~25% (Y1, low BoM scale) toward 70-80% (Y10) as: (a) BoM learning, (b) platform reuse, (c) growing software/AI revenue mix. EBITDA crosses positive earlier than a legacy prime would achieve thanks to concurrent ESM revenue; FCF turns positive shortly after.
B12: Funding strategy | C12: Three stage-gated equity rounds totalling Rs.1,100 Cr (Seed 450, Series A 400, Series B 250) plus Rs.200 Cr venture/PSU debt and Rs.26.5 Cr iDEX/ADITI non-dilutive. BG cash margin 10% (existing facility) frees ~Rs.374 Cr of deployable cash vs legacy 100% margin assumption. No reliance on grant capital for survival - all milestones cash-self-sustaining post-Series B.
B13: Key risks & mitigants | C13: Schedule slip on hardware qualification (mitigant: small cert team + partner-lab leverage + MVP-first releases). Export-control restrictions (mitigant: dual variant ITAR/EAR99 builds, DCS workflow). Talent (mitigant: cleared-engineer pipeline + remote-first software roles + university programs). Customer concentration (mitigant: 6-vertical diversification + allied FMS pipeline from Y2).
B14: How to read this workbook | C14: Strategy to Roadmap to Platform to ReuseMatrix to V1..V6 (verticals) to Revenue (consolidated) to Headcount to R&D_NRE (with reuse savings) to Capex to Opex to P&L to CashFlow to Funding to BreakEven to KPIs.

Sheet MarketPositioning
B2: Competitive landscape - multi-domain platform vs. single-point vendors
B4: Capability dimension | C4: Our platform firm | D4: Tier-1 prime (broad) | E4: Specialty RF vendor | F4: C-UAS pure-play | G4: UAS pure-play | H4: AUV/USV specialist | I4: Defense AI startup
B5: Multi-domain coverage (Air/Land/Sea) | C5: 4 | D5: 4 | E5: 1 | F5: 1 | G5: 2 | H5: 2 | I5: 2
B6: RF / AESA capability | C6: 4 | D6: 4 | E6: 4 | F6: 2 | G6: 1 | H6: 1 | I6: 0
B7: EW / SIGINT capability | C7: 4 | D7: 4 | E7: 3 | F7: 2 | G7: 1 | H7: 1 | I7: 0
B8: Counter-UAS integrated solutions | C8: 3 | D8: 3 | E8: 1 | F8: 4 | G8: 1 | H8: 0 | I8: 1
B9: MALE-class UAS platforms | C9: 3 | D9: 4 | E9: 0 | F9: 0 | G9: 4 | H9: 0 | I9: 0
B10: Autonomous AUV/USV | C10: 3 | D10: 2 | E10: 0 | F10: 0 | G10: 1 | H10: 4 | I10: 0
B11: Military AI / sensor fusion | C11: 4 | D11: 3 | E11: 1 | F11: 2 | G11: 2 | H11: 2 | I11: 4
B12: Platform reuse / amortized NRE | C12: 4 | D12: 2 | E12: 1 | F12: 1 | G12: 1 | H12: 1 | I12: 2
B13: Time-to-market for new variants | C13: 4 | D13: 1 | E13: 2 | F13: 2 | G13: 1 | H13: 2 | I13: 3
B14: Cost-to-deliver (NRE per $ revenue) | C14: 4 | D14: 1 | E14: 3 | F14: 3 | G14: 2 | H14: 3 | I14: 4
B15: Cleared workforce / accredited facilities | C15: 3 | D15: 4 | E15: 3 | F15: 2 | G15: 3 | H15: 2 | I15: 1
B16: Export / FMS readiness | C16: 3 | D16: 4 | E16: 3 | F16: 2 | G16: 3 | H16: 2 | I16: 1
... B19: Capital efficiency (rev per $ raised) | C19: 4 | D19: 2 | E19: 3 | F19: 3 | G19: 1 | H19: 2 | I19: 3
B20: Composite score | C20: =SUM(C5:C19) -> 55 | D20: =SUM(D5:D19) -> 42 | E20: =SUM(E5:E19) -> 29 | F20: =SUM(F5:F19) -> 29 | G20: =SUM(G5:G19) -> 27 | H20: =SUM(H5:H19) -> 27 | I20: =SUM(I5:I19) -> 28
B22: Positioning summary
B23: Score legend | C23: 0 = absent | 1 = weak | 2 = partial | 3 = strong | 4 = leader
B24: Differentiation | C24: Only the platform firm spans all three domains AND amortizes RF/DSP/SysEng/SW/AI across six product lines. Pure-plays may lead in their narrow niche, but pay full NRE per product and lack cross-domain pull-through revenue.
B25: Primes vs. us | C25: Primes lead in scale, customer access and clearances; we lead in cost-to-deliver, time-to-market, and platform reuse. We compete on the 'mid-tier program' tier (sub-INR 500 Cr) where T1 primes are unprofitable.
B26: Path to category leadership | C26: Win 1 marquee program per vertical in Y2-Y5; convert into reference accounts; build allied/FMS pipeline; monetize the Mil-AI / autonomy stack as a software product attached to all hardware lines.

Sheet Roadmap
B2: 10-Year Strategic Roadmap - Platform Waves & Vertical Milestones
B4: Track | C4: Phase / focus | D4: Y1 | E4: Y2 | F4: Y3 | G4: Y4 | H4: Y5 | I4: Y6 | J4: Y7 | K4: Y8 | L4: Y9 | M4: Y10
B5: Platform M1: RF | C5: Carried over from ESM - productize | D5: Q | E5: S | F5: S | G5: S | H5: X | I5: X | J5: X | K5: X | L5: X | M5: X
B6: Platform M2: DSP | C6: Carried over from ESM - productize | D6: Q | E6: S | F6: S | G6: S | H6: X | I6: X | J6: X | K6: X | L6: X | M6: X
B7: Platform M3: SysEng | C7: MIL-STD / integration framework | D7: D | E7: Q | F7: S | G7: S | H7: S | I7: X | J7: X | K7: X | L7: X | M7: X
B8: Platform M4: SW | C8: Mission SW / C2 - productize | D8: Q | E8: S | F8: S | G8: S | H8: X | I8: X | J8: X | K8: X | L8: X | M8: X
B9: Platform M5: AI/ML | C9: Autonomy / fusion (new build) | D9: D | E9: Q | F9: S | G9: S | H9: S | I9: X | J9: X | K9: X | L9: X | M9: X
B10: V2 EW & SIGINT | C10: ESM in production Day-1 + scale-up | D10: S | E10: S | F10: S | G10: X | H10: X | I10: X | J10: X | K10: X | L10: X | M10: X
B11: V6 Military AI | C11: Edge AI + Cloud SaaS - ship Y1 | D11: S | E11: S | F11: S | G11: S | H11: X | I11: X | J11: X | K11: X | L11: X | M11: X
B12: V1 AESA Radar | C12: Variants A/B/C - qualify Y1 ship Y2 | D12: D | E12: Q | F12: S | G12: S | H12: S | I12: X | J12: X | K12: X | L12: X | M12: X
B13: V3 C-UAS | C13: MVP Y2 - multi-layer integrated | D13: D | E13: Q | F13: S | G13: S | H13: S | I13: X | J13: X | K13: X | L13: X | M13: X
B14: V5 Autonomous AUV/USV | C14: Small AUV Y3 to large AUV + USV | D14: R | E14: D | F14: Q | G14: S | H14: S | I14: S | J14: X | K14: X | L14: X | M14: X
B15: V4 MALE UAS | C15: Airframe + airworthiness (longest) | D15: R | E15: D | F15: D | G15: Q | H15: S | I15: S | J15: S | K15: X | L15: X | M15: X
B16: Facilities & cert | C16: Partner labs Y1-Y2 to owned Y3+ | D16: S | E16: S | F16: D | G16: Q | H16: S | I16: S | J16: S | K16: S | L16: S | M16: S
B17: Funding milestones | C17: SeedtoAtoBtoCtoD (smaller late stages) | D17: S | E17: S | F17: S | H17: S | J17: S
B18: Export / FMS | C18: DCS approvals + allied bids from Y2 | D18: R | E18: D | F18: Q | G18: S | H18: S | I18: X | J18: X | K18: X | L18: X | M18: X
B20: Legend
B21: R | C21: Research / seed | D21: D | E21: Develop | F21: Q | G21: Qualify / cert | H21: S | I21: Ship / scale | J21: X | K21: Export / scale-out

Sheet Platform
B2: Shared Platform Modules - Investment Profile & Maturity (TRL-style 0..1)
B4: Module | C4: Scope | D4: Y1 | E4: Y2 | F4: Y3 | G4: Y4 | H4: Y5 | I4: Y6 | J4: Y7 | K4: Y8 | L4: Y9 | M4: Y10
B5: A. Platform NRE investment by module (₹ Cr)
B6: RF / Microwave (T/R modules, receivers, antennas, GaN MMICs) | C6: X/S/Ku-band T/R modules, GaN PA/LNA, beamforming, antenna design - carried over from ESM, now extended to AESA and C-UAS. | D6: 45 | E6: 45 | F6: 25 | G6: 18 | H6: 9 | I6: 4.5 | J6: 2.5 | K6: 2.5 | L6: 2.5 | M6: 0
B7: DSP / Signal Processing (FPGA, SDR, beamforming) | C7: Real-time FPGA pipelines, SDR firmware, DBF - already fielded in ESM; reused across Radar, C-UAS, AI sensor fusion. | D7: 28 | E7: 30 | F7: 13 | G7: 8 | H7: 5 | I7: 3 | J7: 1.5 | K7: 1.5 | L7: 0 | M7: 0
B8: Systems Engineering (mech, thermal, MIL-STD, integration) | C8: MIL-STD-810/461/704 hardening, mechanical/thermal, V&V - every product line consumes this. | D8: 12 | E8: 28 | F8: 17 | G8: 12 | H8: 7 | I8: 3.5 | J8: 2.5 | K8: 1.3 | L8: 1.3 | M8: 1.3
B9: Embedded & Mission Software (RTOS, mission systems, C2) | C9: RTOS, mission computer SW, C2 interfaces, cybersecurity, MOSA/FACE - productized early, shipped with ESM and Mil-AI in Y1. | D9: 6 | E9: 42 | F9: 17 | G9: 9 | H9: 5 | I9: 2.5 | J9: 1.3 | K9: 1.3 | L9: 1.3 | M9: 0
B10: AI / ML (computer vision, sensor fusion, autonomy, MLOps) | C10: CV, sensor fusion, autonomy stack, MLOps - fastest-growing module; heaviest reuse in C-UAS, UAS, AUV/USV, MilAI. | D10: 10 | E10: 65 | F10: 35 | G10: 22 | H10: 12 | I10: 7 | J10: 3.5 | K10: 1.8 | L10: 1.8 | M10: 1.8
B11: Total platform NRE | C11: Sum of all module investment | D11: =SUM(D6:D10) -> 101 | E11: =SUM(E6:E10) -> 210 | F11: =SUM(F6:F10) -> 107 | G11: =SUM(G6:G10) -> 69 | H11: =SUM(H6:H10) -> 38 | I11: =SUM(I6:I10) -> 20.5 | J11: =SUM(J6:J10) -> 11.3 | K11: =SUM(K6:K10) -> 8.4 | ... M11: =SUM(M6:M10) -> 3.1
B12: Cumulative platform NRE | D12: =D11 -> 101 | E12: =D12+E11 -> 311 | F12: =E12+F11 -> 418 | G12: =F12+G11 -> 487 | H12: =G12+H11 -> 525 | I12: =H12+I11 -> 545.5 | J12: =I12+J11 -> 556.8 | K12: =J12+K11 -> 565.2 | L12: =K12+L11 -> 572.1 | M12: =L12+M11 -> 575.2
B14: B. Platform module maturity (0..1) × global reuse multiplier
B15: RF / Microwave (T/R modules, receivers, antennas, GaN MMICs) | C15: TRL-style progression - used as reuse strength | D15: 0.55 | E15: 0.7 | F15: 0.82 | G15: 0.9 | H15: 0.94 | I15: 0.96 | J15: 0.97 | K15: 0.98 | L15: 0.99 | M15: 0.99
B16: DSP / Signal Processing (FPGA, SDR, beamforming) | C16: TRL-style progression - used as reuse strength | D16: 0.6 | E16: 0.75 | F16: 0.85 | G16: 0.91 | H16: 0.95 | I16: 0.97 | J16: 0.98 | K16: 0.99 | L16: 0.99 | M16: 0.99
B17: Systems Engineering (mech, thermal, MIL-STD, integration) | C17: TRL-style progression - used as reuse strength | D17: 0.4 | E17: 0.6 | F17: 0.75 | G17: 0.85 | H17: 0.91 | I17: 0.94 | J17: 0.96 | K17: 0.97 | L17: 0.98 | M17: 0.99
B18: Embedded & Mission Software (RTOS, mission systems, C2) | C18: TRL-style progression - used as reuse strength | D18: 0.5 | E18: 0.7 | F18: 0.83 | G18: 0.9 | H18: 0.94 | I18: 0.96 | J18: 0.97 | K18: 0.98 | L18: 0.99 | M18: 0.99
B19: AI / ML (computer vision, sensor fusion, autonomy, MLOps) | C19: TRL-style progression - used as reuse strength | D19: 0.25 | E19: 0.5 | F19: 0.7 | G19: 0.83 | H19: 0.9 | I19: 0.94 | J19: 0.96 | K19: 0.97 | L19: 0.98 | M19: 0.99
B20: C. Effective reuse strength per module (= maturity × multiplier, capped 1)
B21: RF / Microwave (T/R modules, receivers, antennas, GaN MMICs) - effective | D21: =MIN(1,D15*Assumptions!$C$26) -> 0.55 | E21: =MIN(1,E15*Assumptions!$C$26) -> 0.7 | F21: =MIN(1,F15*Assumptions!$C$26) -> 0.82 | G21: =MIN(1,G15*Assumptions!$C$26) -> 0.9 | H21: =MIN(1,H15*Assumptions!$C$26) -> 0.94 | I21: =MIN(1,I15*Assumptions!$C$26) -> 0.96 | J21: =MIN(1,J15*Assumptions!$C$26) -> 0.97 | K21: =MIN(1,K15*Assumptions!$C$26) -> 0.98 | ... M21: =MIN(1,M15*Assumptions!$C$26) -> 0.99
B22: DSP / Signal Processing (FPGA, SDR, beamforming) - effective | D22: =MIN(1,D16*Assumptions!$C$26) -> 0.6 | E22: =MIN(1,E16*Assumptions!$C$26) -> 0.75 | F22: =MIN(1,F16*Assumptions!$C$26) -> 0.85 | G22: =MIN(1,G16*Assumptions!$C$26) -> 0.91 | H22: =MIN(1,H16*Assumptions!$C$26) -> 0.95 | I22: =MIN(1,I16*Assumptions!$C$26) -> 0.97 | J22: =MIN(1,J16*Assumptions!$C$26) -> 0.98 | K22: =MIN(1,K16*Assumptions!$C$26) -> 0.99 | ... M22: =MIN(1,M16*Assumptions!$C$26) -> 0.99
B23: Systems Engineering (mech, thermal, MIL-STD, integration) - effective | D23: =MIN(1,D17*Assumptions!$C$26) -> 0.4 | E23: =MIN(1,E17*Assumptions!$C$26) -> 0.6 | F23: =MIN(1,F17*Assumptions!$C$26) -> 0.75 | G23: =MIN(1,G17*Assumptions!$C$26) -> 0.85 | H23: =MIN(1,H17*Assumptions!$C$26) -> 0.91 | I23: =MIN(1,I17*Assumptions!$C$26) -> 0.94 | J23: =MIN(1,J17*Assumptions!$C$26) -> 0.96 | K23: =MIN(1,K17*Assumptions!$C$26) -> 0.97 | ... M23: =MIN(1,M17*Assumptions!$C$26) -> 0.99
B24: Embedded & Mission Software (RTOS, mission systems, C2) - effective | D24: =MIN(1,D18*Assumptions!$C$26) -> 0.5 | E24: =MIN(1,E18*Assumptions!$C$26) -> 0.7 | F24: =MIN(1,F18*Assumptions!$C$26) -> 0.83 | G24: =MIN(1,G18*Assumptions!$C$26) -> 0.9 | H24: =MIN(1,H18*Assumptions!$C$26) -> 0.94 | I24: =MIN(1,I18*Assumptions!$C$26) -> 0.96 | J24: =MIN(1,J18*Assumptions!$C$26) -> 0.97 | K24: =MIN(1,K18*Assumptions!$C$26) -> 0.98 | ... M24: =MIN(1,M18*Assumptions!$C$26) -> 0.99
B25: AI / ML (computer vision, sensor fusion, autonomy, MLOps) - effective | D25: =MIN(1,D19*Assumptions!$C$26) -> 0.25 | E25: =MIN(1,E19*Assumptions!$C$26) -> 0.5 | F25: =MIN(1,F19*Assumptions!$C$26) -> 0.7 | G25: =MIN(1,G19*Assumptions!$C$26) -> 0.83 | H25: =MIN(1,H19*Assumptions!$C$26) -> 0.9 | I25: =MIN(1,I19*Assumptions!$C$26) -> 0.94 | J25: =MIN(1,J19*Assumptions!$C$26) -> 0.96 | K25: =MIN(1,K19*Assumptions!$C$26) -> 0.97 | ... M25: =MIN(1,M19*Assumptions!$C$26) -> 0.99

Sheet R&D_Buckets
B2: R&D Buckets - Evidence-led Platform NRE Capitalisation
B3: Policy | C3: Evidence-led: research is expensed; only qualifying development is capitalised; non-eligible development is expensed.
B5: A. Source Platform NRE by module (from Platform sheet)
B6: Module | C6: Source / Check | D6: Y1 | E6: Y2 | F6: Y3 | G6: Y4 | H6: Y5 | I6: Y6 | J6: Y7 | K6: Y8 | L6: Y9 | M6: Y10
B7: RF / Microwave | C7: =Platform!C6 -> X/S/Ku-band T/R modules, GaN PA/LNA, beamforming, antenna design - carried over from ESM, now extended to AESA and C-UAS. | D7: =Platform!D6 -> 45 | E7: =Platform!E6 -> 45 | F7: =Platform!F6 -> 25 | G7: =Platform!G6 -> 18 | H7: =Platform!H6 -> 9 | I7: =Platform!I6 -> 4.5 | J7: =Platform!J6 -> 2.5 | ... M7: =Platform!M6 -> 0
B8: DSP / Signal Processing | C8: =Platform!C7 -> Real-time FPGA pipelines, SDR firmware, DBF - already fielded in ESM; reused across Radar, C-UAS, AI sensor fusion. | D8: =Platform!D7 -> 28 | E8: =Platform!E7 -> 30 | F8: =Platform!F7 -> 13 | G8: =Platform!G7 -> 8 | H8: =Platform!H7 -> 5 | I8: =Platform!I7 -> 3 | J8: =Platform!J7 -> 1.5 | ... M8: =Platform!M7 -> 0
B9: Systems Engineering | C9: =Platform!C8 -> MIL-STD-810/461/704 hardening, mechanical/thermal, V&V - every product line consumes this. | D9: =Platform!D8 -> 12 | E9: =Platform!E8 -> 28 | F9: =Platform!F8 -> 17 | G9: =Platform!G8 -> 12 | H9: =Platform!H8 -> 7 | I9: =Platform!I8 -> 3.5 | J9: =Platform!J8 -> 2.5 | ... M9: =Platform!M8 -> 1.3
B10: Embedded & Mission Software | C10: =Platform!C9 -> RTOS, mission computer SW, C2 interfaces, cybersecurity, MOSA/FACE - productized early, shipped with ESM and Mil-AI in Y1. | D10: =Platform!D9 -> 6 | E10: =Platform!E9 -> 42 | F10: =Platform!F9 -> 17 | G10: =Platform!G9 -> 9 | H10: =Platform!H9 -> 5 | I10: =Platform!I9 -> 2.5 | J10: =Platform!J9 -> 1.3 | ... M10: =Platform!M9 -> 0
B11: AI / ML | C11: =Platform!C10 -> CV, sensor fusion, autonomy stack, MLOps - fastest-growing module; heaviest reuse in C-UAS, UAS, AUV/USV, MilAI. | D11: =Platform!D10 -> 10 | E11: =Platform!E10 -> 65 | F11: =Platform!F10 -> 35 | G11: =Platform!G10 -> 22 | H11: =Platform!H10 -> 12 | I11: =Platform!I10 -> 7 | J11: =Platform!J10 -> 3.5 | ... M11: =Platform!M10 -> 1.8
B12: Total Platform NRE | C12: Check to Platform!D11:M11 | D12: =SUM(D7:D11) -> 101 | E12: =SUM(E7:E11) -> 210 | F12: =SUM(F7:F11) -> 107 | G12: =SUM(G7:G11) -> 69 | H12: =SUM(H7:H11) -> 38 | I12: =SUM(I7:I11) -> 20.5 | J12: =SUM(J7:J11) -> 11.3 | K12: =SUM(K7:K11) -> 8.4 | ... M12: =SUM(M7:M11) -> 3.1
B14: B. Research - expensed % (input)
B15: Module | C15: Accounting treatment | D15: Y1 | E15: Y2 | F15: Y3 | G15: Y4 | H15: Y5 | I15: Y6 | J15: Y7 | K15: Y8 | L15: Y9 | M15: Y10
B16: RF / Microwave | C16: Research phase - expense immediately | D16: 0.5 | E16: 0.35 | F16: 0.2 | G16: 0.15 | H16: 0.1 | I16: 0.1 | J16: 0.05 | K16: 0.05 | L16: 0.05 | M16: 0.05
B17: DSP / Signal Processing | C17: Research phase - expense immediately | D17: 0.45 | E17: 0.3 | F17: 0.18 | G17: 0.12 | H17: 0.08 | I17: 0.05 | J17: 0.05 | K17: 0.05 | L17: 0.05 | M17: 0.05
B18: Systems Engineering | C18: Research phase - expense immediately | D18: 0.35 | E18: 0.25 | F18: 0.15 | G18: 0.1 | H18: 0.08 | I18: 0.05 | J18: 0.05 | K18: 0.05 | L18: 0.05 | M18: 0.05
B19: Embedded & Mission Software | C19: Research phase - expense immediately | D19: 0.4 | E19: 0.25 | F19: 0.15 | G19: 0.1 | H19: 0.08 | I19: 0.05 | J19: 0.05 | K19: 0.05 | L19: 0.05 | M19: 0.05
B20: AI / ML | C20: Research phase - expense immediately | D20: 0.65 | E20: 0.5 | F20: 0.35 | G20: 0.25 | H20: 0.18 | I20: 0.12 | J20: 0.1 | K20: 0.08 | L20: 0.08 | M20: 0.08
B23: C. Development - capitalised % (input)
B24: Module | C24: Accounting treatment | D24: Y1 | E24: Y2 | F24: Y3 | G24: Y4 | H24: Y5 | I24: Y6 | J24: Y7 | K24: Y8 | L24: Y9 | M24: Y10
B25: RF / Microwave | C25: Qualifying development - capitalise | D25: 0.25 | E25: 0.45 | F25: 0.6 | G25: 0.65 | H25: 0.7 | I25: 0.7 | J25: 0.75 | K25: 0.75 | L25: 0.75 | M25: 0.75
B26: DSP / Signal Processing | C26: Qualifying development - capitalise | D26: 0.3 | E26: 0.5 | F26: 0.62 | G26: 0.68 | H26: 0.72 | I26: 0.75 | J26: 0.75 | K26: 0.75 | L26: 0.75 | M26: 0.75
B27: Systems Engineering | C27: Qualifying development - capitalise | D27: 0.25 | E27: 0.4 | F27: 0.55 | G27: 0.65 | H27: 0.7 | I27: 0.72 | J27: 0.75 | K27: 0.75 | L27: 0.75 | M27: 0.75
B28: Embedded & Mission Software | C28: Qualifying development - capitalise | D28: 0.35 | E28: 0.55 | F28: 0.65 | G28: 0.7 | H28: 0.75 | I28: 0.78 | J28: 0.8 | K28: 0.8 | L28: 0.8 | M28: 0.8
B29: AI / ML | C29: Qualifying development - capitalise | D29: 0.15 | E29: 0.3 | F29: 0.45 | G29: 0.55 | H29: 0.62 | I29: 0.68 | J29: 0.7 | K29: 0.72 | L29: 0.72 | M29: 0.72
B32: D. Development - expensed / not capitalisation eligible % (calculated)
B33: Module | C33: Formula | D33: Y1 | E33: Y2 | F33: Y3 | G33: Y4 | H33: Y5 | I33: Y6 | J33: Y7 | K33: Y8 | L33: Y9 | M33: Y10
B34: RF / Microwave | C34: 1 - Research% - Capitalised% | D34: =1-D16-D25 -> 0.25 | E34: =1-E16-E25 -> 0.2 | F34: =1-F16-F25 -> 0.2 | G34: =1-G16-G25 -> 0.2 | H34: =1-H16-H25 -> 0.2 | I34: =1-I16-I25 -> 0.2 | J34: =1-J16-J25 -> 0.2 | K34: =1-K16-K25 -> 0.2 | ... M34: =1-M16-M25 -> 0.2
B35: DSP / Signal Processing | C35: 1 - Research% - Capitalised% | D35: =1-D17-D26 -> 0.25 | E35: =1-E17-E26 -> 0.2 | F35: =1-F17-F26 -> 0.2 | G35: =1-G17-G26 -> 0.2 | H35: =1-H17-H26 -> 0.2 | I35: =1-I17-I26 -> 0.2 | J35: =1-J17-J26 -> 0.2 | K35: =1-K17-K26 -> 0.2 | ... M35: =1-M17-M26 -> 0.2
B36: Systems Engineering | C36: 1 - Research% - Capitalised% | D36: =1-D18-D27 -> 0.4 | E36: =1-E18-E27 -> 0.35 | F36: =1-F18-F27 -> 0.3 | G36: =1-G18-G27 -> 0.25 | H36: =1-H18-H27 -> 0.22 | I36: =1-I18-I27 -> 0.23 | J36: =1-J18-J27 -> 0.2 | K36: =1-K18-K27 -> 0.2 | ... M36: =1-M18-M27 -> 0.2
B37: Embedded & Mission Software | C37: 1 - Research% - Capitalised% | D37: =1-D19-D28 -> 0.25 | E37: =1-E19-E28 -> 0.2 | F37: =1-F19-F28 -> 0.2 | G37: =1-G19-G28 -> 0.2 | H37: =1-H19-H28 -> 0.17 | I37: =1-I19-I28 -> 0.17 | J37: =1-J19-J28 -> 0.15 | K37: =1-K19-K28 -> 0.15 | ... M37: =1-M19-M28 -> 0.15
B38: AI / ML | C38: 1 - Research% - Capitalised% | D38: =1-D20-D29 -> 0.2 | E38: =1-E20-E29 -> 0.2 | F38: =1-F20-F29 -> 0.2 | G38: =1-G20-G29 -> 0.2 | H38: =1-H20-H29 -> 0.2 | I38: =1-I20-I29 -> 0.2 | J38: =1-J20-J29 -> 0.2 | K38: =1-K20-K29 -> 0.2 | ... M38: =1-M20-M29 -> 0.2
B41: E. Bucket % check (must equal 100%)
B42: Module | C42: Check | D42: Y1 | E42: Y2 | F42: Y3 | G42: Y4 | H42: Y5 | I42: Y6 | J42: Y7 | K42: Y8 | L42: Y9 | M42: Y10
B43: RF / Microwave | C43: Research + capitalised + non-eligible | D43: =D16+D25+D34 -> 1 | E43: =E16+E25+E34 -> 1 | F43: =F16+F25+F34 -> 1 | G43: =G16+G25+G34 -> 1 | H43: =H16+H25+H34 -> 1 | I43: =I16+I25+I34 -> 1 | J43: =J16+J25+J34 -> 1 | K43: =K16+K25+K34 -> 1 | ... M43: =M16+M25+M34 -> 1
B44: DSP / Signal Processing | C44: Research + capitalised + non-eligible | D44: =D17+D26+D35 -> 1 | E44: =E17+E26+E35 -> 1 | F44: =F17+F26+F35 -> 1 | G44: =G17+G26+G35 -> 1 | H44: =H17+H26+H35 -> 1 | I44: =I17+I26+I35 -> 1 | J44: =J17+J26+J35 -> 1 | K44: =K17+K26+K35 -> 1 | ... M44: =M17+M26+M35 -> 1
B45: Systems Engineering | C45: Research + capitalised + non-eligible | D45: =D18+D27+D36 -> 1 | E45: =E18+E27+E36 -> 1 | F45: =F18+F27+F36 -> 1 | G45: =G18+G27+G36 -> 1 | H45: =H18+H27+H36 -> 1 | I45: =I18+I27+I36 -> 1 | J45: =J18+J27+J36 -> 1 | K45: =K18+K27+K36 -> 1 | ... M45: =M18+M27+M36 -> 1
B46: Embedded & Mission Software | C46: Research + capitalised + non-eligible | D46: =D19+D28+D37 -> 1 | E46: =E19+E28+E37 -> 1 | F46: =F19+F28+F37 -> 1 | G46: =G19+G28+G37 -> 1 | H46: =H19+H28+H37 -> 1 | I46: =I19+I28+I37 -> 1 | J46: =J19+J28+J37 -> 1 | K46: =K19+K28+K37 -> 1 | ... M46: =M19+M28+M37 -> 1
B47: AI / ML | C47: Research + capitalised + non-eligible | D47: =D20+D29+D38 -> 1 | E47: =E20+E29+E38 -> 1 | F47: =F20+F29+F38 -> 1 | G47: =G20+G29+G38 -> 1 | H47: =H20+H29+H38 -> 1 | I47: =I20+I29+I38 -> 1 | J47: =J20+J29+J38 -> 1 | K47: =K20+K29+K38 -> 1 | ... M47: =M20+M29+M38 -> 1
B49: Check status | C49: OK if all years/modules = 100% | D49: =IF(AND(D43=1,D44=1,D45=1,D46=1,D47=1),"OK","CHECK") -> OK | E49: =IF(AND(E43=1,E44=1,E45=1,E46=1,E47=1),"OK","CHECK") -> OK | F49: =IF(AND(F43=1,F44=1,F45=1,F46=1,F47=1),"OK","CHECK") -> OK | G49: =IF(AND(G43=1,G44=1,G45=1,G46=1,G47=1),"OK","CHECK") -> OK | H49: =IF(AND(H43=1,H44=1,H45=1,H46=1,H47=1),"OK","CHECK") -> OK | I49: =IF(AND(I43=1,I44=1,I45=1,I46=1,I47=1),"OK","CHECK") -> OK | J49: =IF(AND(J43=1,J44=1,J45=1,J46=1,J47=1),"OK","CHECK") -> OK | K49: =IF(AND(K43=1,K44=1,K45=1,K46=1,K47=1),"OK","CHECK") -> OK | ... M49: =IF(AND(M43=1,M44=1,M45=1,M46=1,M47=1),"OK","CHECK") -> OK
B52: F. Research - expensed amount (INR Cr)
...

Sheet ReuseMatrix
B2: gross x (1 - reuse savings); all values in INR Crores
B4: A. Module composition per vertical (rows sum to 100%) - input
B5: Vertical | C5: M1_RF | D5: M2_DSP | E5: M3_SYSENG | F5: M4_SW | G5: M5_AI | H5: Row total (check)
B6: V1 - AESA Radar | C6: 0.45 | D6: 0.25 | E6: 0.2 | F6: 0.08 | G6: 0.02 | H6: =SUM(C6:G6) -> 1
B7: V2 - Electronic Warfare & SIGINT | C7: 0.4 | D7: 0.3 | E7: 0.15 | F7: 0.1 | G7: 0.05 | H7: =SUM(C7:G7) -> 1
B8: V3 - Counter-UAS (Anti-Drone) | C8: 0.25 | D8: 0.2 | E8: 0.15 | F8: 0.15 | G8: 0.25 | H8: =SUM(C8:G8) -> 1
B9: V4 - MALE-class ISR UAS | C9: 0.05 | D9: 0.1 | E9: 0.4 | F9: 0.25 | G9: 0.2 | H9: =SUM(C9:G9) -> 1
B10: V5 - Autonomous Systems (AUV/USV) | C10: 0.05 | D10: 0.1 | E10: 0.35 | F10: 0.25 | G10: 0.25 | H10: =SUM(C10:G10) -> 1
B11: V6 - Military AI Systems | C11: 0 | D11: 0.1 | E11: 0.05 | F11: 0.25 | G11: 0.6 | H11: =SUM(C11:G11) -> 1
B13: B. Effective reuse savings % per vertical per year (= composition × platform maturity)
B14: Vertical | D14: Y1 | E14: Y2 | F14: Y3 | G14: Y4 | H14: Y5 | I14: Y6 | J14: Y7 | K14: Y8 | L14: Y9 | M14: Y10
B15: V1 - AESA Radar | D15: =C6*Platform!D21+D6*Platform!D22+E6*Platform!D23+F6*Platform!D24+G6*Platform!D25 -> 0.5225 | E15: =C6*Platform!E21+D6*Platform!E22+E6*Platform!E23+F6*Platform!E24+G6*Platform!E25 -> 0.6885 | F15: =C6*Platform!F21+D6*Platform!F22+E6*Platform!F23+F6*Platform!F24+G6*Platform!F25 -> 0.8119 | G15: =C6*Platform!G21+D6*Platform!G22+E6*Platform!G23+F6*Platform!G24+G6*Platform!G25 -> 0.8911 | H15: =C6*Platform!H21+D6*Platform!H22+E6*Platform!H23+F6*Platform!H24+G6*Platform!H25 -> 0.9357 | I15: =C6*Platform!I21+D6*Platform!I22+E6*Platform!I23+F6*Platform!I24+G6*Platform!I25 -> 0.9581 | J15: =C6*Platform!J21+D6*Platform!J22+E6*Platform!J23+F6*Platform!J24+G6*Platform!J25 -> 0.9703 | K15: =C6*Platform!K21+D6*Platform!K22+E6*Platform!K23+F6*Platform!K24+G6*Platform!K25 -> 0.9803 | L15: =C6*Platform!L21+D6*Platform!L22+E6*Platform!L23+F6*Platform!L24+G6*Platform!L25 -> 0.9878 | M15: =C6*Platform!M21+D6*Platform!M22+E6*Platform!M23+F6*Platform!M24+G6*Platform!M25 -> 0.99
B16: V2 - Electronic Warfare & SIGINT | D16: =C7*Platform!D21+D7*Platform!D22+E7*Platform!D23+F7*Platform!D24+G7*Platform!D25 -> 0.5225 | E16: =C7*Platform!E21+D7*Platform!E22+E7*Platform!E23+F7*Platform!E24+G7*Platform!E25 -> 0.69 | F16: =C7*Platform!F21+D7*Platform!F22+E7*Platform!F23+F7*Platform!F24+G7*Platform!F25 -> 0.8135 | G16: =C7*Platform!G21+D7*Platform!G22+E7*Platform!G23+F7*Platform!G24+G7*Platform!G25 -> 0.892 | H16: =C7*Platform!H21+D7*Platform!H22+E7*Platform!H23+F7*Platform!H24+G7*Platform!H25 -> 0.9365 | I16: =C7*Platform!I21+D7*Platform!I22+E7*Platform!I23+F7*Platform!I24+G7*Platform!I25 -> 0.959 | J16: =C7*Platform!J21+D7*Platform!J22+E7*Platform!J23+F7*Platform!J24+G7*Platform!J25 -> 0.971 | K16: =C7*Platform!K21+D7*Platform!K22+E7*Platform!K23+F7*Platform!K24+G7*Platform!K25 -> 0.981 | L16: =C7*Platform!L21+D7*Platform!L22+E7*Platform!L23+F7*Platform!L24+G7*Platform!L25 -> 0.988 | M16: =C7*Platform!M21+D7*Platform!M22+E7*Platform!M23+F7*Platform!M24+G7*Platform!M25 -> 0.99
B17: V3 - Counter-UAS (Anti-Drone) | D17: =C8*Platform!D21+D8*Platform!D22+E8*Platform!D23+F8*Platform!D24+G8*Platform!D25 -> 0.455 | E17: =C8*Platform!E21+D8*Platform!E22+E8*Platform!E23+F8*Platform!E24+G8*Platform!E25 -> 0.645 | F17: =C8*Platform!F21+D8*Platform!F22+E8*Platform!F23+F8*Platform!F24+G8*Platform!F25 -> 0.787 | G17: =C8*Platform!G21+D8*Platform!G22+E8*Platform!G23+F8*Platform!G24+G8*Platform!G25 -> 0.877 | H17: =C8*Platform!H21+D8*Platform!H22+E8*Platform!H23+F8*Platform!H24+G8*Platform!H25 -> 0.9275 | I17: =C8*Platform!I21+D8*Platform!I22+E8*Platform!I23+F8*Platform!I24+G8*Platform!I25 -> 0.954 | J17: =C8*Platform!J21+D8*Platform!J22+E8*Platform!J23+F8*Platform!J24+G8*Platform!J25 -> 0.968 | K17: =C8*Platform!K21+D8*Platform!K22+E8*Platform!K23+F8*Platform!K24+G8*Platform!K25 -> 0.978 | L17: =C8*Platform!L21+D8*Platform!L22+E8*Platform!L23+F8*Platform!L24+G8*Platform!L25 -> 0.986 | M17: =C8*Platform!M21+D8*Platform!M22+E8*Platform!M23+F8*Platform!M24+G8*Platform!M25 -> 0.99
B18: V4 - MALE-class ISR UAS | D18: =C9*Platform!D21+D9*Platform!D22+E9*Platform!D23+F9*Platform!D24+G9*Platform!D25 -> 0.4225 | E18: =C9*Platform!E21+D9*Platform!E22+E9*Platform!E23+F9*Platform!E24+G9*Platform!E25 -> 0.625 | F18: =C9*Platform!F21+D9*Platform!F22+E9*Platform!F23+F9*Platform!F24+G9*Platform!F25 -> 0.7735 | G18: =C9*Platform!G21+D9*Platform!G22+E9*Platform!G23+F9*Platform!G24+G9*Platform!G25 -> 0.867 | H18: =C9*Platform!H21+D9*Platform!H22+E9*Platform!H23+F9*Platform!H24+G9*Platform!H25 -> 0.921 | I18: =C9*Platform!I21+D9*Platform!I22+E9*Platform!I23+F9*Platform!I24+G9*Platform!I25 -> 0.949 | J18: =C9*Platform!J21+D9*Platform!J22+E9*Platform!J23+F9*Platform!J24+G9*Platform!J25 -> 0.965 | K18: =C9*Platform!K21+D9*Platform!K22+E9*Platform!K23+F9*Platform!K24+G9*Platform!K25 -> 0.975 | L18: =C9*Platform!L21+D9*Platform!L22+E9*Platform!L23+F9*Platform!L24+G9*Platform!L25 -> 0.984 | M18: =C9*Platform!M21+D9*Platform!M22+E9*Platform!M23+F9*Platform!M24+G9*Platform!M25 -> 0.99
B19: V5 - Autonomous Systems (AUV/USV) | D19: =C10*Platform!D21+D10*Platform!D22+E10*Platform!D23+F10*Platform!D24+G10*Platform!D25 -> 0.415 | E19: =C10*Platform!E21+D10*Platform!E22+E10*Platform!E23+F10*Platform!E24+G10*Platform!E25 -> 0.62 | F19: =C10*Platform!F21+D10*Platform!F22+E10*Platform!F23+F10*Platform!F24+G10*Platform!F25 -> 0.771 | G19: =C10*Platform!G21+D10*Platform!G22+E10*Platform!G23+F10*Platform!G24+G10*Platform!G25 -> 0.866 | H19: =C10*Platform!H21+D10*Platform!H22+E10*Platform!H23+F10*Platform!H24+G10*Platform!H25 -> 0.9205 | I19: =C10*Platform!I21+D10*Platform!I22+E10*Platform!I23+F10*Platform!I24+G10*Platform!I25 -> 0.949 | J19: =C10*Platform!J21+D10*Platform!J22+E10*Platform!J23+F10*Platform!J24+G10*Platform!J25 -> 0.965 | K19: =C10*Platform!K21+D10*Platform!K22+E10*Platform!K23+F10*Platform!K24+G10*Platform!K25 -> 0.975 | L19: =C10*Platform!L21+D10*Platform!L22+E10*Platform!L23+F10*Platform!L24+G10*Platform!L25 -> 0.984 | M19: =C10*Platform!M21+D10*Platform!M22+E10*Platform!M23+F10*Platform!M24+G10*Platform!M25 -> 0.99
B20: V6 - Military AI Systems | D20: =C11*Platform!D21+D11*Platform!D22+E11*Platform!D23+F11*Platform!D24+G11*Platform!D25 -> 0.355 | E20: =C11*Platform!E21+D11*Platform!E22+E11*Platform!E23+F11*Platform!E24+G11*Platform!E25 -> 0.58 | F20: =C11*Platform!F21+D11*Platform!F22+E11*Platform!F23+F11*Platform!F24+G11*Platform!F25 -> 0.75 | G20: =C11*Platform!G21+D11*Platform!G22+E11*Platform!G23+F11*Platform!G24+G11*Platform!G25 -> 0.8565 | H20: =C11*Platform!H21+D11*Platform!H22+E11*Platform!H23+F11*Platform!H24+G11*Platform!H25 -> 0.9155 | I20: =C11*Platform!I21+D11*Platform!I22+E11*Platform!I23+F11*Platform!I24+G11*Platform!I25 -> 0.948 | J20: =C11*Platform!J21+D11*Platform!J22+E11*Platform!J23+F11*Platform!J24+G11*Platform!J25 -> 0.9645 | K20: =C11*Platform!K21+D11*Platform!K22+E11*Platform!K23+F11*Platform!K24+G11*Platform!K25 -> 0.9745 | L20: =C11*Platform!L21+D11*Platform!L22+E11*Platform!L23+F11*Platform!L24+G11*Platform!L25 -> 0.9835 | M20: =C11*Platform!M21+D11*Platform!M22+E11*Platform!M23+F11*Platform!M24+G11*Platform!M25 -> 0.99
B22: C. Vertical-specific NRE - gross (standalone) vs leveraged (post platform reuse)
B23: Vertical / line | C23: Driver | D23: Y1 | E23: Y2 | F23: Y3 | G23: Y4 | H23: Y5 | I23: Y6 | J23: Y7 | K23: Y8 | L23: Y9 | M23: Y10
B24: AESA Gross NRE | C24: Total ~209 INR Cr over 10y | D24: 62.7 | E24: 62.7 | F24: 37.62 | G24: 20.9 | H24: 10.45 | I24: 6.27 | J24: 4.18 | K24: 2.09 | L24: 1.045 | M24: 1.045
A25: AESA Radar | B25: Gross NRE | C25: Gross = Standalone NRE × Gross Drivers, Net = Gross × (1 − Reuse Savings), where savings from 2026 onwards | D25: =D24*(1-D15) -> 29.93925 | E25: =E24*(1-E15) -> 19.53105 | F25: =F24*(1-F15) -> 7.076322 | G25: =G24*(1-G15) -> 2.27601 | H25: =H24*(1-H15) -> 0.671935 | I25: =I24*(1-I15) -> 0.262713 | J25: =J24*(1-J15) -> 0.124146 | K25: =K24*(1-K15) -> 0.041173 | ... M25: =M24*(1-M15) -> 0.01045
B26: V1 NRE savings from platform - ₹ Cr/yr | D26: =D24-D25 -> 32.76075 | E26: =E24-E25 -> 43.16895 | F26: =F24-F25 -> 30.543678 | G26: =G24-G25 -> 18.62399 | H26: =H24-H25 -> 9.778065 | I26: =I24-I25 -> 6.007287 | J26: =J24-J25 -> 4.055854 | K26: =K24-K25 -> 2.048827 | ... M26: =M24-M25 -> 1.03455
B27: EW/SIGINT Gross NRE | C27: Total ~114 INR Cr over 10y | D27: 45.6 | E27: 34.2 | F27: 17.1 | G27: 7.98 | H27: 4.56 | I27: 2.28 | J27: 1.14 | K27: 0.57 | L27: 0.57 | M27: 0
A28: EW/SIGINT | B28: Gross NRE | C28: Gross = Standalone NRE × Gross Drivers, Net = Gross × (1 − Reuse Savings) | D28: =D27*(1-D16) -> 21.774 | E28: =E27*(1-E16) -> 10.602 | F28: =F27*(1-F16) -> 3.18915 | G28: =G27*(1-G16) -> 0.86184 | H28: =H27*(1-H16) -> 0.28956 | I28: =I27*(1-I16) -> 0.09348 | J28: =J27*(1-J16) -> 0.03306 | K28: =K27*(1-K16) -> 0.01083 | ... M28: =M27*(1-M16) -> 0
B29: V2 NRE savings from platform - ₹ Cr/yr | D29: =D27-D28 -> 23.826 | E29: =E27-E28 -> 23.598 | F29: =F27-F28 -> 13.91085 | G29: =G27-G28 -> 7.11816 | H29: =H27-H28 -> 4.27044 | I29: =I27-I28 -> 2.18652 | J29: =J27-J28 -> 1.10694 | K29: =K27-K28 -> 0.55917 | ... M29: =M27-M28 -> 0
B30: C-UAS Gross NRE | C30: Total ~152 INR Cr over 10y | D30: 38 | E30: 45.6 | F30: 30.4 | G30: 15.2 | H30: 9.12 | I30: 6.08 | J30: 3.04 | K30: 2.28 | L30: 0.76 | M30: 0.76
A31: C-UAS | B31: Gross NRE | C31: Gross = Standalone NRE × Gross Drivers, Net = Gross × (1 − Reuse Savings) | D31: =D30*(1-D17) -> 20.71 | E31: =E30*(1-E17) -> 16.188 | F31: =F30*(1-F17) -> 6.4752 | G31: =G30*(1-G17) -> 1.8696 | H31: =H30*(1-H17) -> 0.6612 | I31: =I30*(1-I17) -> 0.27968 | J31: =J30*(1-J17) -> 0.09728 | K31: =K30*(1-K17) -> 0.05016 | ... M31: =M30*(1-M17) -> 0.0076
B32: V3 NRE savings from platform - ₹ Cr/yr | D32: =D30-D31 -> 17.29 | E32: =E30-E31 -> 29.412 | F32: =F30-F31 -> 23.9248 | G32: =G30-G31 -> 13.3304 | H32: =H30-H31 -> 8.4588 | I32: =I30-I31 -> 5.80032 | J32: =J30-J31 -> 2.94272 | K32: =K30-K31 -> 2.22984 | ... M32: =M30-M31 -> 0.7524
B33: MALE UAS Gross NRE | C33: Total ~523 INR Cr over 10y | D33: 41.8 | E33: 78.375 | F33: 114.95 | G33: 114.95 | H33: 78.375 | I33: 41.8 | J33: 26.125 | K33: 15.675 | L33: 5.225 | M33: 5.225
A34: MALE UAS | B34: Gross NRE | C34: Gross = Standalone NRE × Gross Drivers, Net = Gross × (1 − Reuse Savings) | D34: =D33*(1-D18) -> 24.1395 | E34: =E33*(1-E18) -> 29.390625 | F34: =F33*(1-F18) -> 26.036175 | G34: =G33*(1-G18) -> 15.28835 | H34: =H33*(1-H18) -> 6.191625 | I34: =I33*(1-I18) -> 2.1318 | J34: =J33*(1-J18) -> 0.914375 | K34: =K33*(1-K18) -> 0.391875 | ... M34: =M33*(1-M18) -> 0.05225
B35: V4 NRE savings from platform - ₹ Cr/yr | D35: =D33-D34 -> 17.6605 | E35: =E33-E34 -> 48.984375 | F35: =F33-F34 -> 88.913825 | G35: =G33-G34 -> 99.66165 | H35: =H33-H34 -> 72.183375 | I35: =I33-I34 -> 39.6682 | J35: =J33-J34 -> 25.210625 | K35: =K33-K34 -> 15.283125 | ... M35: =M33-M34 -> 5.17275
B36: Autonomous Gross NRE | C36: Total ~247 INR Cr over 10y | D36: 37.05 | E36: 61.75 | F36: 54.34 | G36: 37.05 | H36: 24.7 | I36: 14.82 | J36: 9.88 | K36: 4.94 | L36: 1.235 | M36: 1.235
A37: Autonomous Systems | B37: Gross NRE | C37: Gross = Standalone NRE × Gross Drivers, Net = Gross × (1 − Reuse Savings) | D37: =D36*(1-D19) -> 21.67425 | E37: =E36*(1-E19) -> 23.465 | F37: =F36*(1-F19) -> 12.44386 | G37: =G36*(1-G19) -> 4.9647 | H37: =H36*(1-H19) -> 1.96365 | I37: =I36*(1-I19) -> 0.75582 | J37: =J36*(1-J19) -> 0.3458 | K37: =K36*(1-K19) -> 0.1235 | ... M37: =M36*(1-M19) -> 0.01235
B38: V5 NRE savings from platform - ₹ Cr/yr | D38: =D36-D37 -> 15.37575 | E38: =E36-E37 -> 38.285 | F38: =F36-F37 -> 41.89614 | G38: =G36-G37 -> 32.0853 | H38: =H36-H37 -> 22.73635 | I38: =I36-I37 -> 14.06418 | J38: =J36-J37 -> 9.5342 | K38: =K36-K37 -> 4.8165 | ... M38: =M36-M37 -> 1.22265
B39: Mil AI Gross NRE | C39: Total ~105 INR Cr over 10y | D39: 36.575 | E39: 26.125 | F39: 15.675 | G39: 10.45 | H39: 6.27 | I39: 4.18 | J39: 3.135 | K39: 1.5675 | L39: 0.5225 | M39: 0.5225
A40: Mil AI / Analytics | B40: Gross NRE | C40: Gross = Standalone NRE × Gross Drivers, Net = Gross × (1 − Reuse Savings) | D40: =D39*(1-D20) -> 23.590875 | E40: =E39*(1-E20) -> 10.9725 | F40: =F39*(1-F20) -> 3.91875 | G40: =G39*(1-G20) -> 1.499575 | H40: =H39*(1-H20) -> 0.529815 | I40: =I39*(1-I20) -> 0.21736 | J40: =J39*(1-J20) -> 0.1112925 | K40: =K39*(1-K20) -> 0.03997125 | ... M40: =M39*(1-M20) -> 0.005225
B41: V6 NRE savings from platform - ₹ Cr/yr | D41: =D39-D40 -> 12.984125 | E41: =E39-E40 -> 15.1525 | F41: =F39-F40 -> 11.75625 | G41: =G39-G40 -> 8.950425 | H41: =H39-H40 -> 5.740185 | I41: =I39-I40 -> 3.96264 | J41: =J39-J40 -> 3.0237075 | K41: =K39-K40 -> 1.5275287 | ... M41: =M39-M40 -> 0.517275
B43: D. Portfolio NRE totals (sum across V1..V6 + standalone platform investment)
B44: Aggregate line | D44: Y1 | E44: Y2 | F44: Y3 | G44: Y4 | H44: Y5 | I44: Y6 | J44: Y7 | K44: Y8 | L44: Y9 | M44: Y10
B45: Σ Gross NRE (verticals, standalone) | D45: =D24+D27+D30+D33+D36+D39 -> 261.725 | E45: =E24+E27+E30+E33+E36+E39 -> 308.75 | F45: =F24+F27+F30+F33+F36+F39 -> 270.085 | G45: =G24+G27+G30+G33+G36+G39 -> 206.53 | H45: =H24+H27+H30+H33+H36+H39 -> 133.475 | I45: =I24+I27+I30+I33+I36+I39 -> 75.43 | J45: =J24+J27+J30+J33+J36+J39 -> 47.5 | K45: =K24+K27+K30+K33+K36+K39 -> 27.1225 | ... M45: =M24+M27+M30+M33+M36+M39 -> 8.7875
...

Sheet Assumptions
B2: Global planning assumptions
B3: Driver | C3: Value | D3: Note
B4: Planning currency | C4: INR Crores | D4: Displayed in INR Crores (₹ Cr). Underlying inputs in absolute INR; 1 Cr = 10^7 INR; 1 USD = 95 INR.
B5: Planning horizon (years) | C5: 10 | D5: 10-year strategic horizon.
B6: Corporate tax rate | C6: 0.25 | D6: Blended.
B7: Discount rate (WACC) | C7: 0.18 | D7: Used for NPV - 18% reflects unlisted Indian defense unlisted equity cost-of-capital (β~1.5, ERP 8-9%, Rf 7%).
B8: Cost escalation (annual) | C8: 0.04 | D8: General wages + opex inflator (COGS/S&M/G&A roles & opex).
B9: R&D salary escalation (annual) | C9: 0.04 | D9: [M9 fix: reduced from 12% to 4% - aligns with general Indian wage growth long-term. 12% was unsustainable over 10y.]
B10: BoM learning curve (per doubling) | C10: 0.92 | D10: Wright's-law: cost factor at double cumulative volume.
B11: DSO (days sales outstanding) | C11: 180 | D11: Realistic blended DSO: iDEX/Make-II ~90-120d, MoD CapEx ~240-365d, export ~120d. Blended 180d.
B12: DPO (days payable outstanding) | C12: 45 | D12: Supplier terms net-45 typical for cleared vendors.
B13: Inventory days | C13: 90 | D13: Long-lead RF/FPGA components offset by JIT mission-SW & VMI.
B14: - (row retired) | D14: Legacy WC% removed. WC is now driven by DSO/DPO/Inventory schedule. Row left blank to preserve cell references below.
B15: S&M as % of revenue | C15: 0.08 | D15: Sales, BD, demos, exhibitions.
B16: G&A as % of revenue | C16: 0.07 | D16: Finance/HR/Legal/Compliance.
B17: Bid & Proposal as % of revenue | C17: 0.03 | D17: Capture/B&P overhead in defense.
B18: Export control overhead | C18: 2 | D18: Annual base, escalating.
B19: Cybersecurity / CMMC L3 overhead | C19: 14.25 | D19: Annual base, escalating.
B20: Quality / AS9100 / CMMI overhead | C20: 8.55 | D20: Annual base, escalating.
B21: Performance guarantee rate (PBG) | C21: 0.03 | D21: PBG % of contract value held by customer's bank through delivery period.
B22: Advance payment rate | C22: 0.15 | D22: Mobilization advance from MoD typical 15% against ABG.
B23: Bank guarantee fee (annual) | C23: 0.011 | D23: Reduced from 1.5% given Rs.150 Cr land/factory collateral provides physical security to issuing bank.
B24: Cash collateral requirement | C24: See Backlog!63 | D24: Year-specific schedule applied in Backlog!D63:M63 - Y1 100%, Y2 100%, Y3 50%, Y4 30%, Y5-Y10 20% (full collateral while bank track-record is being built, tapering as PBG/ABG history matures).
B25: Min cash reserve target | C25: 100 | D25: Triggers funding rounds.
B26: Platform reuse maturity multiplier | C26: 1 | D26: Scenario lever on reuse savings (1.0 = base).
B28: Defense-specific operating context
A29: ASP_elasticity | B29: ASP price erosion exponent (ASP elasticity to BoM): 0.5 means ASP declines with sqrt(BoM). | C29: 0.5
A30: BoM_floor | B30: Minimum BoM as fraction of starting BoM (learning curve floor): 0.7 means BoM cannot fall below 70% of initial. | C30: 0.7
B31: Contract types | C31: Fixed-price (FP), Cost-plus-fixed-fee (CPFF), IDIQ, FMS/Direct Commercial Sale.
B32: Compliance baseline | C32: ITAR / EAR / CMMC L3 / AS9100 / CMMI L3 - modeled in Opex.
B33: Qualification cycles | C33: MIL-STD-810 (env), -461 (EMI/EMC), -704 (power), -1275/704 - modeled in Capex (test infra).
B34: Export model | C34: Direct Commercial Sale (DCS) + FMS-eligible variants; offset obligations factored in S&M.
B35: IP / data rights | C35: Default to retain Government-Purpose Rights; unlimited rights only when negotiated separately.
B36: Defensive moats | C36: Platform IP + qualified BoM + cleared personnel + accredited facilities + customer references.
B37: MAT rate (Minimum Alternate Tax) | C37: 0.15 | D37: India Sec 115JB book-profit floor. Excess over regular tax becomes MAT credit asset.
B38: Column convention (READ BEFORE EDITING) | C38: Y1 column varies by sheet | D38: Y1 = col C on: P&L, CashFlow, BalanceSheet, BreakEven, KPIs (metric rows). Y1 = col D on: Revenue, Headcount, Capex, Opex, Funding, Backlog, V1-V6, R&D_NRE, Platform, ReuseMatrix. Cross-sheet formulas compensate today. DO NOT INSERT COLUMNS without re-auditing every cross-sheet reference.
B39: ASP price-cost elasticity exponent | C39: 0.5 | D39: Exponent linking ASP reduction to BoM cost reduction. 0.5 = square-root relationship.
B40: BoM floor (% of initial) | C40: 0.7 | D40: Minimum BoM cost as % of initial BoM after full learning curve absorption.
B41: Learning curve doubling basis | C41: 2 | D41: Logarithm base for Wrights-law learning curve (doubles of cumulative volume).
B42: USD to INR conversion rate | C42: 95 | D42: Planning exchange rate for any USD-based inputs.
...

Sheet V1_AESA
B1: READ ONLY SUPPORTING DETAIL - Revenue is recognized via Backlog!Section L (rows 89-95). Editing units/ASP here does NOT change consolidated revenue, but DOES rescale COGS (BoM x delivered_rev / V-sheet rev). Do not edit unless you intend to re-baseline the BoM ratio.
B2: V1 - AESA Radar | Domain: Air/Land/Sea (RF) | Launch: Y2
B3: Description | C3: Active Electronically Scanned Array radars - second product line; leverages partly-developed ESM RF & DSP front-end. First demo Y2, first deliveries Y2.
B5: Line | C5: Driver | D5: Y1 | E5: Y2 | F5: Y3 | G5: Y4 | H5: Y5 | I5: Y6 | J5: Y7 | K5: Y8 | L5: Y9 | M5: Y10
B6: Variant A - X-band Airborne
B7: ASP / unit (₹ Cr) | C7: yellow = input | D7: 26 | E7: =$D$7*(E8/$D$8)^Assumptions!$C$39 -> 22.637384 | F7: =$D$7*(F8/$D$8)^Assumptions!$C$39 -> 21.753161 | G7: =$D$7*(G8/$D$8)^Assumptions!$C$39 -> 21.753161 | H7: =$D$7*(H8/$D$8)^Assumptions!$C$39 -> 21.753161 | I7: =$D$7*(I8/$D$8)^Assumptions!$C$39 -> 21.753161 | J7: =$D$7*(J8/$D$8)^Assumptions!$C$39 -> 21.753161 | K7: =$D$7*(K8/$D$8)^Assumptions!$C$39 -> 21.753161 | L7: =$D$7*(L8/$D$8)^Assumptions!$C$39 -> 21.753161 | M7: =$D$7*(M8/$D$8)^Assumptions!$C$39 -> 21.753161
B8: BoM / unit (₹ Cr) | C8: yellow = input | D8: 11 | E8: =MAX($D$8*Assumptions!$C$40,$D$8*Assumptions!$C$10^LOG(MAX(1,SUM($D9:E9)),Assumptions!$C$41)) -> 8.338702 | F8: =MAX($D$8*Assumptions!$C$40,$D$8*Assumptions!$C$10^LOG(MAX(1,SUM($D9:F9)),Assumptions!$C$41)) -> 7.7 | G8: =MAX($D$8*Assumptions!$C$40,$D$8*Assumptions!$C$10^LOG(MAX(1,SUM($D9:G9)),Assumptions!$C$41)) -> 7.7 | H8: =MAX($D$8*Assumptions!$C$40,$D$8*Assumptions!$C$10^LOG(MAX(1,SUM($D9:H9)),Assumptions!$C$41)) -> 7.7 | I8: =MAX($D$8*Assumptions!$C$40,$D$8*Assumptions!$C$10^LOG(MAX(1,SUM($D9:I9)),Assumptions!$C$41)) -> 7.7 | J8: =MAX($D$8*Assumptions!$C$40,$D$8*Assumptions!$C$10^LOG(MAX(1,SUM($D9:J9)),Assumptions!$C$41)) -> 7.7 | K8: =MAX($D$8*Assumptions!$C$40,$D$8*Assumptions!$C$10^LOG(MAX(1,SUM($D9:K9)),Assumptions!$C$41)) -> 7.7 | L8: =MAX($D$8*Assumptions!$C$40,$D$8*Assumptions!$C$10^LOG(MAX(1,SUM($D9:L9)),Assumptions!$C$41)) -> 7.7 | M8: =MAX($D$8*Assumptions!$C$40,$D$8*Assumptions!$C$10^LOG(MAX(1,SUM($D9:M9)),Assumptions!$C$41)) -> 7.7
B9: Units shipped (#) | C9: yellow = input | D9: 2 | E9: 8 | F9: 10 | G9: 20 | H9: 50 | I9: 50 | J9: 60 | K9: 60 | L9: 80 | M9: 80
B10: Revenue (units × ASP) | D10: =D7*D9 -> 52 | E10: =E7*E9 -> 181.09907 | F10: =F7*F9 -> 217.53161 | G10: =G7*G9 -> 435.06321 | H10: =H7*H9 -> 1087.658 | I10: =I7*I9 -> 1087.658 | J10: =J7*J9 -> 1305.1896 | K10: =K7*K9 -> 1305.1896 | ... M10: =M7*M9 -> 1740.2529
B11: COGS - BoM (units × BoM) | D11: =D8*D9 -> 22 | E11: =E8*E9 -> 66.709616 | F11: =F8*F9 -> 77 | G11: =G8*G9 -> 154 | H11: =H8*H9 -> 385 | I11: =I8*I9 -> 385 | J11: =J8*J9 -> 462 | K11: =K8*K9 -> 462 | ... M11: =M8*M9 -> 616
B12: Contribution margin / unit | D12: =IF(D7=0,0,1-D8/D7) -> 0.57692308 | E12: =IF(E7=0,0,1-E8/E7) -> 0.63164021 | F12: =IF(F7=0,0,1-F8/F7) -> 0.64602845 | G12: =IF(G7=0,0,1-G8/G7) -> 0.64602845 | H12: =IF(H7=0,0,1-H8/H7) -> 0.64602845 | I12: =IF(I7=0,0,1-I8/I7) -> 0.64602845 | J12: =IF(J7=0,0,1-J8/J7) -> 0.64602845 | K12: =IF(K7=0,0,1-K8/K7) -> 0.64602845 | ... M12: =IF(M7=0,0,1-M8/M7) -> 0.64602845
B14: Variant B - S-band Ground Surveillance
B15: ASP / unit (₹ Cr) | C15: yellow = input | D15: 45 | E15: =$D$15*(E16/$D$16)^Assumptions!$C$39 -> 45 | F15: =$D$15*(F16/$D$16)^Assumptions!$C$39 -> 42.122588 | G15: =$D$15*(G16/$D$16)^Assumptions!$C$39 -> 40.402567 | H15: =$D$15*(H16/$D$16)^Assumptions!$C$39 -> 39.180087 | I15: =$D$15*(I16/$D$16)^Assumptions!$C$39 -> 38.236138 | J15: =$D$15*(J16/$D$16)^Assumptions!$C$39 -> 37.649701 | K15: =$D$15*(K16/$D$16)^Assumptions!$C$39 -> 37.649701 | L15: =$D$15*(L16/$D$16)^Assumptions!$C$39 -> 37.649701 | M15: =$D$15*(M16/$D$16)^Assumptions!$C$39 -> 37.649701
B16: BoM / unit (₹ Cr) | C16: yellow = input | D16: 17.765 | E16: =MAX($D$16*Assumptions!$C$40,$D$16*Assumptions!$C$10^LOG(MAX(1,SUM($D17:E17)),Assumptions!$C$41)) -> 17.765 | F16: =MAX($D$16*Assumptions!$C$40,$D$16*Assumptions!$C$10^LOG(MAX(1,SUM($D17:F17)),Assumptions!$C$41)) -> 15.565758 | G16: =MAX($D$16*Assumptions!$C$40,$D$16*Assumptions!$C$10^LOG(MAX(1,SUM($D17:G17)),Assumptions!$C$41)) -> 14.320497 | H16: =MAX($D$16*Assumptions!$C$40,$D$16*Assumptions!$C$10^LOG(MAX(1,SUM($D17:H17)),Assumptions!$C$41)) -> 13.467004 | I16: =MAX($D$16*Assumptions!$C$40,$D$16*Assumptions!$C$10^LOG(MAX(1,SUM($D17:I17)),Assumptions!$C$41)) -> 12.825911 | J16: =MAX($D$16*Assumptions!$C$40,$D$16*Assumptions!$C$10^LOG(MAX(1,SUM($D17:J17)),Assumptions!$C$41)) -> 12.4355 | K16: =MAX($D$16*Assumptions!$C$40,$D$16*Assumptions!$C$10^LOG(MAX(1,SUM($D17:K17)),Assumptions!$C$41)) -> 12.4355 | L16: =MAX($D$16*Assumptions!$C$40,$D$16*Assumptions!$C$10^LOG(MAX(1,SUM($D17:L17)),Assumptions!$C$41)) -> 12.4355 | M16: =MAX($D$16*Assumptions!$C$40,$D$16*Assumptions!$C$10^LOG(MAX(1,SUM($D17:M17)),Assumptions!$C$41)) -> 12.4355
B17: Units shipped (#) | C17: yellow = input | D17: 0 | E17: 1 | F17: 2 | G17: 3 | H17: 4 | I17: 5 | J17: 6 | K17: 7 | L17: 8 | M17: 8
B18: Revenue (units × ASP) | D18: =D15*D17 -> 0 | E18: =E15*E17 -> 45 | F18: =F15*F17 -> 84.245176 | G18: =G15*G17 -> 121.2077 | H18: =H15*H17 -> 156.72035 | I18: =I15*I17 -> 191.18069 | J18: =J15*J17 -> 225.89821 | K18: =K15*K17 -> 263.54791 | ... M18: =M15*M17 -> 301.19761
B19: COGS - BoM (units × BoM) | D19: =D16*D17 -> 0 | E19: =E16*E17 -> 17.765 | F19: =F16*F17 -> 31.131516 | G19: =G16*G17 -> 42.961492 | H19: =H16*H17 -> 53.868015 | I19: =I16*I17 -> 64.129554 | J19: =J16*J17 -> 74.613 | K19: =K16*K17 -> 87.0485 | ... M19: =M16*M17 -> 99.484
